# [üìò Errores y excepciones en Python](https://github.com/YonRasgg/Curso-de-Python-Desde-Cero/blob/main/10.%20GestionErrores/1.Errores.py)

Como mencion√© antes, en Python hay dos tipos principales de errores: errores de sintaxis y excepciones. Los errores de sintaxis son problemas con el c√≥digo que impiden que Python lo ejecute correctamente, mientras que las excepciones son errores que ocurren durante la ejecuci√≥n del programa.

Python proporciona mecanismos para manejar las excepciones a trav√©s de los bloques `try`, `except`, `else`, y `finally`.

## üõ†Ô∏è Manejo de excepciones con `try`, `except`, `else`, y `finally`

El bloque `try` contiene el c√≥digo que puede causar una excepci√≥n. Si ocurre una excepci√≥n en el bloque `try`, la ejecuci√≥n se detiene inmediatamente y se pasa al bloque `except`. Si no ocurre ninguna excepci√≥n, el bloque `except` se ignora.

El bloque `finally` contiene c√≥digo que se ejecuta independientemente de si se produce una excepci√≥n o no. Es √∫til para limpiar recursos o ejecutar acciones que deben suceder en todas las circunstancias.

Aqu√≠ tienes un desglose del codigo ejemplo:

```python
while(True):
    try:
        # C√≥digo que puede causar una excepci√≥n
        edad = int(input("Introduce tu edad: "))    
        print("Tu edad es: ", edad)
        break
    except:
        # C√≥digo que se ejecuta si ocurre una excepci√≥n
        print("Ha ocurrido un error, introduce bien la edad")
    finally:
        # C√≥digo que se ejecuta siempre, independientemente de si se produce una excepci√≥n o no
        print("Fin de la iteraci√≥n")
```

En este ejemplo, el programa solicita al usuario que introduzca su edad. Si el usuario introduce un n√∫mero, se imprime la edad y se rompe el bucle. Si el usuario introduce algo que no puede convertirse en un n√∫mero (lo que causa una `ValueError`), el bloque `except` se ejecuta, informando al usuario de que ha ocurrido un error y pidi√©ndole que introduzca correctamente la edad. Independientemente de lo que suceda, el bloque `finally` se ejecuta e imprime "Fin de la iteraci√≥n".

Es importante destacar que manejar todas las excepciones con un `except` gen√©rico, como se hace en este ejemplo, no se considera una buena pr√°ctica. Es mejor manejar espec√≠ficamente las excepciones que esperas que puedan ocurrir. En este caso, podr√≠amos manejar espec√≠ficamente la `ValueError` que sabemos que puede ocurrir:

```python
while(True):
    try:
        edad = int(input("Introduce tu edad: "))    
        print("Tu edad es: ", edad)
        break
    except ValueError:
        print("Ha ocurrido un error, introduce bien la edad")
    finally:
        print("Fin de la iteraci√≥n")
```

[< Retroceder](https://github.com/YonRasgg/Curso-de-Python-Desde-Cero/blob/main/10.%20GestionErrores/Introduccion.md) | [Ver Codigo Fuente](https://github.com/YonRasgg/Curso-de-Python-Desde-Cero/blob/main/10.%20GestionErrores/1.Errores.py) | [Siguiente >](https://github.com/YonRasgg/Curso-de-Python-Desde-Cero/blob/main/10.%20GestionErrores/2.ExcepcionesMultiples.md)
